<?xml version="1.0" encoding="utf-8"?>
<!-- This URDF was automatically created by SolidWorks to URDF Exporter! Originally created by Stephen Brawner (brawner@gmail.com) 
     Commit Version: 1.5.1-0-g916b5db  Build Version: 1.5.7152.31018
     For more information, please see http://wiki.ros.org/sw_urdf_exporter -->
<robot
  name="robot_urdf">
  <link
    name="base_link">
    <inertial>
      <origin
        xyz="-0.022501 0.03264 0.1665"
        rpy="0 0 0" />
      <mass
        value="75.231" />
      <inertia
        ixx="14.838"
        ixy="0.0052526"
        ixz="-0.0049976"
        iyy="6.8"
        iyz="0.060805"
        izz="19.798" />
    </inertial>
    <visual>
      <origin
        xyz="0 0 0"
        rpy="0 0 0" />
      <geometry>
        <mesh
          filename="package://robot_urdf/meshes/base_Link.dae" />
      </geometry>
      <material
        name="">
        <color
          rgba="1 1 1 1" />
      </material>
    </visual>
    <collision>
      <origin
        xyz="0 0 0"
        rpy="0 0 0" />
      <geometry>
        <mesh
          filename="package://robot_urdf/meshes/base_Link.dae" />
      </geometry>
    </collision>
  </link>
  <link
    name="R_W_Link">
    <inertial>
      <origin
        xyz="0 0 0.075"
        rpy="0 0 0" />
      <mass
        value="3.6702" />
      <inertia
        ixx="0.012253"
        ixy="4.3368E-19"
        ixz="2.8934E-19"
        iyy="0.012253"
        iyz="-1.3989E-19"
        izz="0.018211" />
    </inertial>
    <visual>
      <origin
        xyz="0 0 0"
        rpy="0 0 0" />
      <geometry>
        <mesh
          filename="package://robot_urdf/meshes/R_W_Link.STL" />
      </geometry>
      <material
        name="">
        <color
          rgba="0.29804 0.29804 0.29804 1" />
      </material>
    </visual>
    <collision>
      <origin
        xyz="0 0 0"
        rpy="0 0 0" />
      <geometry>
        <mesh
          filename="package://robot_urdf/meshes/R_W_Link.STL" />
      </geometry>
    </collision>
  </link>
  <joint
    name="R_W"
    type="continuous">
    <origin
      xyz="0.20256 0.015054 0.1"
      rpy="1.5708 0.47816 1.5708" />
    <parent
      link="base_link" />
    <child
      link="R_W_Link" />
    <axis
      xyz="0 0 -1" />
  </joint>
  <link
    name="L_W_Link">
    <inertial>
      <origin
        xyz="4.1633E-17 -3.1225E-17 -0.075"
        rpy="0 0 0" />
      <mass
        value="3.6702" />
      <inertia
        ixx="0.012253"
        ixy="-4.3368E-19"
        ixz="8.5115E-19"
        iyy="0.012253"
        iyz="3.4366E-19"
        izz="0.018211" />
    </inertial>
    <visual>
      <origin
        xyz="0 0 0"
        rpy="0 0 0" />
      <geometry>
        <mesh
          filename="package://robot_urdf/meshes/L_W_Link.STL" />
      </geometry>
      <material
        name="">
        <color
          rgba="0.29804 0.29804 0.29804 1" />
      </material>
    </visual>
    <collision>
      <origin
        xyz="0 0 0"
        rpy="0 0 0" />
      <geometry>
        <mesh
          filename="package://robot_urdf/meshes/L_W_Link.STL" />
      </geometry>
    </collision>
  </link>
  <joint
    name="L_W"
    type="continuous">
    <origin
      xyz="-0.24744 0.015054 0.1"
      rpy="1.5708 1.3637 1.5708" />
    <parent
      link="base_link" />
    <child
      link="L_W_Link" />
    <axis
      xyz="0 0 -1" />
  </joint>
  <link
    name="F_B_Link">
    <inertial>
      <origin
        xyz="0.0067551 0.00073425 0.024059"
        rpy="0 0 0" />
      <mass
        value="0.075869" />
      <inertia
        ixx="1.8967E-05"
        ixy="3.7058E-22"
        ixz="0"
        iyy="1.8967E-05"
        iyz="0"
        izz="1.8967E-05" />
    </inertial>
    <visual>
      <origin
        xyz="0 0 0"
        rpy="0 0 0" />
      <geometry>
        <mesh
          filename="package://robot_urdf/meshes/F_B_Link.STL" />
      </geometry>
      <material
        name="">
        <color
          rgba="0.29804 0.29804 0.29804 1" />
      </material>
    </visual>
    <collision>
      <origin
        xyz="0 0 0"
        rpy="0 0 0" />
      <geometry>
        <mesh
          filename="package://robot_urdf/meshes/F_B_Link.STL" />
      </geometry>
    </collision>
  </link>
  <joint
    name="F_B"
    type="fixed">
    <origin
      xyz="-0.022436 0.65449 0"
      rpy="0.03051 -0.2736 -0.024957" />
    <parent
      link="base_link" />
    <child
      link="F_B_Link" />
    <axis
      xyz="0.2702 0.02937 0.96236" />
  </joint>
  <link
    name="B_B_Link">
    <inertial>
      <origin
        xyz="0.0022702 0.0049124 0.024407"
        rpy="0 0 0" />
      <mass
        value="0.075869" />
      <inertia
        ixx="1.8967E-05"
        ixy="1.8529E-22"
        ixz="-1.0588E-22"
        iyy="1.8967E-05"
        iyz="-1.0588E-21"
        izz="1.8967E-05" />
    </inertial>
    <visual>
      <origin
        xyz="0 0 0"
        rpy="0 0 0" />
      <geometry>
        <mesh
          filename="package://robot_urdf/meshes/B_B_Link.STL" />
      </geometry>
      <material
        name="">
        <color
          rgba="0.29804 0.29804 0.29804 1" />
      </material>
    </visual>
    <collision>
      <origin
        xyz="0 0 0"
        rpy="0 0 0" />
      <geometry>
        <mesh
          filename="package://robot_urdf/meshes/B_B_Link.STL" />
      </geometry>
    </collision>
  </link>
  <joint
    name="B_B"
    type="fixed">
    <origin
      xyz="-0.022436 -0.62438 0"
      rpy="0.19862 -0.090934 0.1036" />
    <parent
      link="base_link" />
    <child
      link="B_B_Link" />
    <axis
      xyz="0.090809 0.1965 0.97629" />
  </joint>
  <link
    name="PISTON_Link">
    <inertial>
      <origin
        xyz="-1.7347E-17 1.3357E-16 0.055782"
        rpy="0 0 0" />
      <mass
        value="14.212" />
      <inertia
        ixx="1.9521"
        ixy="1.0607E-16"
        ixz="-2.6529E-18"
        iyy="0.066675"
        iyz="-4.5969E-17"
        izz="2.0018" />
    </inertial>
    <visual>
      <origin
        xyz="0 0 0"
        rpy="0 0 0" />
      <geometry>
        <mesh
          filename="package://robot_urdf/meshes/PISTON_Link.dae" />
      </geometry>
      <material
        name="">
        <color
          rgba="1 1 1 1" />
      </material>
    </visual>
    <collision>
      <origin
        xyz="0 0 0"
        rpy="0 0 0" />
      <geometry>
        <mesh
          filename="package://robot_urdf/meshes/PISTON_Link.dae" />
      </geometry>
    </collision>
  </link>
  <joint
    name="PISTON"
    type="prismatic">
    <origin
      xyz="-0.022436 0.015054 0.335"
      rpy="0 0 0" />
    <parent
      link="base_link" />
    <child
      link="PISTON_Link" />
    <axis
      xyz="0 0 1" />
    <limit
      lower="-0.06"
      upper="0.05"
      effort="1000E+06"
      velocity="1000E+06" />
  </joint>
  <link
    name="F_Grip_Link">
    <inertial>
      <origin
        xyz="-2.498E-16 -2.4321E-15 0.075"
        rpy="0 0 0" />
      <mass
        value="3" />
      <inertia
        ixx="0.0057813"
        ixy="-2.7064E-19"
        ixz="-4.3946E-19"
        iyy="0.008125"
        iyz="-4.4046E-19"
        izz="0.0026563" />
    </inertial>
    <visual>
      <origin
        xyz="0 0 0"
        rpy="0 0 0" />
      <geometry>
        <mesh
          filename="package://robot_urdf/meshes/F_Grip_Link.STL" />
      </geometry>
      <material
        name="">
        <color
          rgba="1 1 1 1" />
      </material>
    </visual>
    <collision>
      <origin
        xyz="0 0 0"
        rpy="0 0 0" />
      <geometry>
        <mesh
          filename="package://robot_urdf/meshes/F_Grip_Link.STL" />
      </geometry>
    </collision>
  </link>
  <joint
    name="F_Grip"
    type="prismatic">
    <origin
      xyz="-0.022436 0.015054 0.125"
      rpy="0 0 0" />
    <parent
      link="base_link" />
    <child
      link="F_Grip_Link" />
    <axis
      xyz="0 0 1" />
    <limit
      lower="0"
      upper="0.20"
      effort="1E+06"
      velocity="1E+06" />
  </joint>
  <!--gazebo differantial drive plugin-->
 <gazebo>
   <plugin name="differential_drive_controller" filename="libgazebo_ros_diff_drive.so">
    <updateRate>50</updateRate>
    <leftJoint>L_W</leftJoint>  
    <rightJoint>R_W</rightJoint>
    <wheelSeparation>0.6</wheelSeparation>
    <wheelDiameter>0.2</wheelDiameter>
    <wheelAcceleration>50.0</wheelAcceleration>
    <wheelTorque>500</wheelTorque>
    <commandTopic>cmd_vel</commandTopic>
    <odometryTopic>odom</odometryTopic>
    <odometryFrame>odom</odometryFrame>
    <robotBaseFrame>base_link</robotBaseFrame>
    <odometrySource>world</odometrySource>
    <publishWheelTF>false</publishWheelTF>
    <publishOdom>true</publishOdom>
    <publishWheelJointState>true</publishWheelJointState>
    <legacyMode>false</legacyMode>
    <rosDebugLevel>na</rosDebugLevel>
    <publishOdomTF>true</publishOdomTF>

  </plugin>
</gazebo>
<gazebo reference ="L_W_Link">
    <mu1>1000</mu1>
    <mu2>1000</mu2>
  </gazebo>
  <gazebo reference ="R_W_Link">
    <mu1>1000</mu1>
    <mu2>1000</mu2>
  </gazebo>
   <gazebo reference ="F_B_Link">
    <mu1>0.1</mu1>
    <mu2>0.1</mu2>
  </gazebo>
  <gazebo reference ="B_B_Link">
    <mu1>0.1</mu1>
    <mu2>0.1</mu2>
  </gazebo>

  <!--transmission 1 piston accutator-->
<transmission name="tran1">
    <type>transmission_interface/SimpleTransmission</type>
    <joint name="PISTON">
      <hardwareInterface>hardware_interface/EffortJointInterface</hardwareInterface>
    </joint>
    <actuator name="motor1">
      <hardwareInterface>hardware_interface/EffortJointInterface</hardwareInterface>
      <mechanicalReduction>1</mechanicalReduction>
    </actuator>
  </transmission>

<!--transmission 2 blockers accutator-->
  <transmission name="tran2">
    <type>transmission_interface/SimpleTransmission</type>
    <joint name="F_Grip">
      <hardwareInterface>hardware_interface/EffortJointInterface</hardwareInterface>
    </joint>
    <actuator name="motor2">
      <hardwareInterface>hardware_interface/EffortJointInterface</hardwareInterface>
      <mechanicalReduction>1</mechanicalReduction>
    </actuator>
  </transmission>
<!--Gazebo plugin for ros_control-->
<gazebo>
  <plugin name="gazebo_ros_control" filename="libgazebo_ros_control.so">
    <robotSimType>gazebo_ros_control/DefaultRobotHWSim</robotSimType>
  </plugin>
</gazebo>

</robot>